<?xml version="1.0"?>

<robot name="obstacle" xmlns:xacro="http://ros.org/wiki/xacro">
	<xacro:property name="obs_width" value="0.25" />
	<xacro:property name="obs_hight" value="1.6" />
	<xacro:property name="obs_offset" value="0.83" />

  	<xacro:include filename="$(find turtlebot_description)/urdf/obstacle.gazebo" />
	<xacro:include filename="$(find turtlebot_description)/urdf/materials.xacro" />

	<link name="obstacle_link">
		<static>1</static>
		<collision name='collision'>
			<origin xyz="0 0 0" rpy="0 0 0" />
			<geometry>
				<cylinder radius="${obs_width}" length = "${obs_hight}"/>
			</geometry>
		</collision>

		<visual>
			<origin xyz="0 0 0" rpy="0 0 0" />
			<geometry>
				<cylinder radius="${obs_width}" length = "${obs_hight}"/>
			</geometry>
			<material name="black"/>
		</visual>

		<inertial>
			<mass value="0.02" />
			<origin xyz="0 0 0.0" />
			<inertia ixx="0.01" ixy="0.0" ixz="0.0"
				iyy="0.01" iyz="0.0" izz="0.5" />
		</inertial>

	</link>

	<joint name="obstacle_joint" type="fixed">
		<origin xyz="0 0 ${obs_offset}" rpy="0 0 0"/>
		<parent link="base_link"/>
		<child link="obstacle_link"/>
	</joint>

	<link name="base_link">
		<static>1</static>
		<inertial>
		<mass value="2" />
		<origin xyz="0 0 0.0" />
		<inertia ixx="0.01" ixy="0.0" ixz="0.0"
			iyy="0.01" iyz="0.0" izz="0.5" />
		</inertial>
	
		<visual>
		<origin xyz=" 0 0 0.0308" rpy="0 0 0" />
		<geometry>
			<mesh filename="package://turtlebot_description/meshes/create_body.dae"/>
		</geometry>
		</visual>
	
		<collision>
		<origin xyz="0.0 0.0 0.0308" rpy="0 0 0" />
		<geometry>
			<cylinder length="0.0611632" radius="0.16495"/>
		</geometry>
		</collision>
	</link>
	
	<link name="left_wheel_link">
		<inertial>
		<origin xyz="0 0 0"/>
		<mass value="0.01" />
		<inertia ixx="0.001" ixy="0.0" ixz="0.0"
			iyy="0.001" iyz="0.0" izz="0.001" />
		</inertial>
	
		<visual>
		<origin xyz="0 0 0" rpy="0 1.5707 1.5707" />
		<geometry>
			<cylinder radius="0.033" length = "0.023"/>
		</geometry>
		</visual>
	
		<collision>
		<origin xyz="0 0 0" rpy="0 1.5707 1.5707" />
		<geometry>
			<cylinder radius="0.033" length = "0.023"/>
		</geometry>
		</collision>
	</link>
	
	<joint name="left_wheel_joint" type="continuous">
		<origin xyz="0 0.13 0.015" rpy="0 0 0"/>
		<parent link="base_link"/>
		<child link="left_wheel_link"/>
		<axis xyz="0 1 0"/>
	</joint>
	
	<link name="right_wheel_link">
		<inertial>
		<origin xyz="0 0 0"/>
		<mass value="0.01" />
		<inertia ixx="0.001" ixy="0.0" ixz="0.0"
			iyy="0.001" iyz="0.0" izz="0.001" />
		</inertial>
	
		<visual>
		<origin xyz="0 0 0" rpy="0 1.5707 1.5707" />
		<geometry>
			<cylinder radius="0.033" length = "0.023"/>
		</geometry>
		</visual>
	
		<collision>
		<origin xyz="0 0 0" rpy="0 1.5707 1.5707" />
		<geometry>
			<cylinder radius="0.033" length = "0.023"/>
		</geometry>
		</collision>
	</link>
	
	<joint name="right_wheel_joint" type="continuous">
		<origin xyz="0 -0.13 0.015" rpy="0 0 0"/>
		<parent link="base_link"/>
		<child link="right_wheel_link"/>
		<axis xyz="0 1 0"/>
	</joint>
	
	<link name="rear_wheel_link">
		<inertial>
			<origin xyz="0 0 0"/>
			<mass value="0.001" />
			<inertia ixx="0.0001" ixy="0.0" ixz="0.0"
				iyy="0.0001" iyz="0.0" izz="0.0001" />
		</inertial>
	
		<visual>
			<origin xyz="0 0 0" rpy="0 1.5707 1.5707"/>
			<geometry>
				<sphere radius="0.015" />
			</geometry>
		</visual>
	
		<collision>
			<origin xyz="0 0 0" rpy="0 1.5707 1.5707" />
			<geometry>
				<sphere radius="0.015" />
			</geometry>
		</collision>
	</link>
	<!-- fixed because there's no transmission -->
	<joint name="rear_castor_joint" type="fixed">
		<origin xyz="-0.13 0 0.0" rpy="0 0 0"/>
		<parent link="base_link"/>
		<child link="rear_wheel_link"/>
		<axis xyz="0 1 0"/>
	</joint>
	
	<link name="front_wheel_link">
		<inertial>
			<origin xyz="0 0 0" />
			<mass value="0.01" />
			<inertia ixx="0.001" ixy="0.0" ixz="0.0"
				iyy="0.001" iyz="0.0" izz="0.001" />
		</inertial>
	
		<visual>
			<origin xyz="0 0 0" rpy="0 1.5707 1.5707"/>
			<geometry>
				<sphere radius="0.018" />
			</geometry>
		</visual>
	
		<collision>
			<origin xyz="0 0 0" rpy="0 1.5707 1.5707" />
			<geometry>
				<sphere radius="0.018" />
			</geometry>
		</collision>
	</link>
	
	<!-- fixed because there's no transmission -->
	<joint name="front_castor_joint" type="fixed">
		<origin xyz="0.13 0 0.0" rpy="0 0 0"/>
		<parent link="base_link"/>
		<child link="front_wheel_link"/>
		<axis xyz="0 1 0"/>
	</joint>

</robot>